2023-10-06 12:44:22 | ERROR    | __main__:run:126 | An error has been caught in function 'run', process 'MainProcess' (3557), thread 'MainThread' (139721318108224): - {}
Traceback (most recent call last):
  File "/home/runner/work/egames4/egames4/epic/src/claim.py", line 120, in stash
    await self.claim_epic_games(context)
  File "/home/runner/work/egames4/egames4/epic/src/claim.py", line 102, in claim_epic_games
    await epic.claim_weekly_games(page, self.promotions)
  File "/home/runner/work/egames4/egames4/epic/src/services/agents/epic_games.py", line 225, in claim_weekly_games
    await page.wait_for_url(URL_CART_SUCCESS)
  File "/opt/hostedtoolcache/Python/3.10.13/x64/lib/python3.10/site-packages/playwright/async_api/_generated.py", line 9408, in wait_for_url
    await self._impl_obj.wait_for_url(
  File "/opt/hostedtoolcache/Python/3.10.13/x64/lib/python3.10/site-packages/playwright/_impl/_page.py", line 497, in wait_for_url
    return await self._main_frame.wait_for_url(**locals_to_params(locals()))
  File "/opt/hostedtoolcache/Python/3.10.13/x64/lib/python3.10/site-packages/playwright/_impl/_frame.py", line 226, in wait_for_url
    async with self.expect_navigation(
  File "/opt/hostedtoolcache/Python/3.10.13/x64/lib/python3.10/site-packages/playwright/_impl/_event_context_manager.py", line 33, in __aexit__
    await self._future
  File "/opt/hostedtoolcache/Python/3.10.13/x64/lib/python3.10/site-packages/playwright/_impl/_frame.py", line 207, in continuation
    await self._wait_for_load_state_impl(state=wait_until, timeout=t)
  File "/opt/hostedtoolcache/Python/3.10.13/x64/lib/python3.10/site-packages/playwright/_impl/_frame.py", line 264, in _wait_for_load_state_impl
    await wait_helper.result()
playwright._impl._api_types.TimeoutError: Timeout 25421ms exceeded.

During handling of the above exception, another exception occurred:

Traceback (most recent call last):
  File "/home/runner/work/egames4/egames4/epic/src/claim.py", line 130, in <module>
    asyncio.run(run())
  File "/opt/hostedtoolcache/Python/3.10.13/x64/lib/python3.10/asyncio/runners.py", line 44, in run
    return loop.run_until_complete(main)
  File "/opt/hostedtoolcache/Python/3.10.13/x64/lib/python3.10/asyncio/base_events.py", line 636, in run_until_complete
    self.run_forever()
  File "/opt/hostedtoolcache/Python/3.10.13/x64/lib/python3.10/asyncio/base_events.py", line 603, in run_forever
    self._run_once()
  File "/opt/hostedtoolcache/Python/3.10.13/x64/lib/python3.10/asyncio/base_events.py", line 1909, in _run_once
    handle._run()
  File "/opt/hostedtoolcache/Python/3.10.13/x64/lib/python3.10/asyncio/events.py", line 80, in _run
    self._context.run(self._callback, *self._args)
> File "/home/runner/work/egames4/egames4/epic/src/claim.py", line 126, in run
    await agent.stash()
  File "/home/runner/work/egames4/egames4/epic/src/claim.py", line 109, in stash
    async with async_playwright() as p:
  File "/opt/hostedtoolcache/Python/3.10.13/x64/lib/python3.10/site-packages/playwright/async_api/_context_manager.py", line 58, in __aexit__
    await self._connection.stop_async()
  File "/opt/hostedtoolcache/Python/3.10.13/x64/lib/python3.10/site-packages/playwright/_impl/_connection.py", line 284, in stop_async
    self.cleanup(error_message)
  File "/opt/hostedtoolcache/Python/3.10.13/x64/lib/python3.10/site-packages/playwright/_impl/_connection.py", line 295, in cleanup
    callback.future.set_exception(Error(error_message))
asyncio.exceptions.InvalidStateError: invalid state
