{"text": "2023-10-14 12:42:53 | INFO    | __main__:stash:119 | run - {'role': 'EpicPlayer', 'headless': True}\n", "record": {"elapsed": {"repr": "0:00:00.951503", "seconds": 0.951503}, "exception": null, "extra": {"role": "EpicPlayer", "headless": true}, "file": {"name": "claim.py", "path": "/home/runner/work/egames4/egames4/epic/src/claim.py"}, "function": "stash", "level": {"icon": "ℹ️", "name": "INFO", "no": 20}, "line": 119, "message": "run", "module": "claim", "name": "__main__", "process": {"id": 4053, "name": "MainProcess"}, "thread": {"id": 140424010996800, "name": "MainThread"}, "time": {"repr": "2023-10-14 12:42:53.632038+08:00", "timestamp": 1697258573.632038}}}
{"text": "2023-10-14 12:43:00 | ERROR    | __main__:run:138 | An error has been caught in function 'run', process 'MainProcess' (4053), thread 'MainThread' (140424010996800): - {}\nTraceback (most recent call last):\n  File \"/opt/hostedtoolcache/Python/3.10.13/x64/lib/python3.10/site-packages/httpcore/_exceptions.py\", line 10, in map_exceptions\n    yield\n  File \"/opt/hostedtoolcache/Python/3.10.13/x64/lib/python3.10/site-packages/httpcore/_backends/sync.py\", line 126, in read\n    return self._sock.recv(max_bytes)\n  File \"/opt/hostedtoolcache/Python/3.10.13/x64/lib/python3.10/ssl.py\", line 1292, in recv\n    return self.read(buflen)\n  File \"/opt/hostedtoolcache/Python/3.10.13/x64/lib/python3.10/ssl.py\", line 1165, in read\n    return self._sslobj.read(len)\nTimeoutError: The read operation timed out\n\nThe above exception was the direct cause of the following exception:\n\nTraceback (most recent call last):\n  File \"/opt/hostedtoolcache/Python/3.10.13/x64/lib/python3.10/site-packages/httpx/_transports/default.py\", line 66, in map_httpcore_exceptions\n    yield\n  File \"/opt/hostedtoolcache/Python/3.10.13/x64/lib/python3.10/site-packages/httpx/_transports/default.py\", line 228, in handle_request\n    resp = self._pool.handle_request(req)\n  File \"/opt/hostedtoolcache/Python/3.10.13/x64/lib/python3.10/site-packages/httpcore/_sync/connection_pool.py\", line 262, in handle_request\n    raise exc\n  File \"/opt/hostedtoolcache/Python/3.10.13/x64/lib/python3.10/site-packages/httpcore/_sync/connection_pool.py\", line 245, in handle_request\n    response = connection.handle_request(request)\n  File \"/opt/hostedtoolcache/Python/3.10.13/x64/lib/python3.10/site-packages/httpcore/_sync/connection.py\", line 103, in handle_request\n    return self._connection.handle_request(request)\n  File \"/opt/hostedtoolcache/Python/3.10.13/x64/lib/python3.10/site-packages/httpcore/_sync/http11.py\", line 133, in handle_request\n    raise exc\n  File \"/opt/hostedtoolcache/Python/3.10.13/x64/lib/python3.10/site-packages/httpcore/_sync/http11.py\", line 111, in handle_request\n    ) = self._receive_response_headers(**kwargs)\n  File \"/opt/hostedtoolcache/Python/3.10.13/x64/lib/python3.10/site-packages/httpcore/_sync/http11.py\", line 176, in _receive_response_headers\n    event = self._receive_event(timeout=timeout)\n  File \"/opt/hostedtoolcache/Python/3.10.13/x64/lib/python3.10/site-packages/httpcore/_sync/http11.py\", line 212, in _receive_event\n    data = self._network_stream.read(\n  File \"/opt/hostedtoolcache/Python/3.10.13/x64/lib/python3.10/site-packages/httpcore/_backends/sync.py\", line 124, in read\n    with map_exceptions(exc_map):\n  File \"/opt/hostedtoolcache/Python/3.10.13/x64/lib/python3.10/contextlib.py\", line 153, in __exit__\n    self.gen.throw(typ, value, traceback)\n  File \"/opt/hostedtoolcache/Python/3.10.13/x64/lib/python3.10/site-packages/httpcore/_exceptions.py\", line 14, in map_exceptions\n    raise to_exc(exc) from exc\nhttpcore.ReadTimeout: The read operation timed out\n\nThe above exception was the direct cause of the following exception:\n\nTraceback (most recent call last):\n  File \"/home/runner/work/egames4/egames4/epic/src/claim.py\", line 142, in <module>\n    asyncio.run(run())\n  File \"/opt/hostedtoolcache/Python/3.10.13/x64/lib/python3.10/asyncio/runners.py\", line 44, in run\n    return loop.run_until_complete(main)\n  File \"/opt/hostedtoolcache/Python/3.10.13/x64/lib/python3.10/asyncio/base_events.py\", line 636, in run_until_complete\n    self.run_forever()\n  File \"/opt/hostedtoolcache/Python/3.10.13/x64/lib/python3.10/asyncio/base_events.py\", line 603, in run_forever\n    self._run_once()\n  File \"/opt/hostedtoolcache/Python/3.10.13/x64/lib/python3.10/asyncio/base_events.py\", line 1909, in _run_once\n    handle._run()\n  File \"/opt/hostedtoolcache/Python/3.10.13/x64/lib/python3.10/asyncio/events.py\", line 80, in _run\n    self._context.run(self._callback, *self._args)\n> File \"/home/runner/work/egames4/egames4/epic/src/claim.py\", line 138, in run\n    await agent.stash()\n  File \"/home/runner/work/egames4/egames4/epic/src/claim.py\", line 130, in stash\n    solver.install(upgrade=True)\n  File \"/opt/hostedtoolcache/Python/3.10.13/x64/lib/python3.10/site-packages/hcaptcha_challenger/__init__.py\", line 67, in install\n    modelhub.assets.flush_runtime_assets(upgrade=upgrade)\n  File \"/opt/hostedtoolcache/Python/3.10.13/x64/lib/python3.10/site-packages/hcaptcha_challenger/onnx/modelhub.py\", line 164, in flush_runtime_assets\n    resp = httpx.get(self.release_url, timeout=3)\n  File \"/opt/hostedtoolcache/Python/3.10.13/x64/lib/python3.10/site-packages/httpx/_api.py\", line 189, in get\n    return request(\n  File \"/opt/hostedtoolcache/Python/3.10.13/x64/lib/python3.10/site-packages/httpx/_api.py\", line 100, in request\n    return client.request(\n  File \"/opt/hostedtoolcache/Python/3.10.13/x64/lib/python3.10/site-packages/httpx/_client.py\", line 814, in request\n    return self.send(request, auth=auth, follow_redirects=follow_redirects)\n  File \"/opt/hostedtoolcache/Python/3.10.13/x64/lib/python3.10/site-packages/httpx/_client.py\", line 901, in send\n    response = self._send_handling_auth(\n  File \"/opt/hostedtoolcache/Python/3.10.13/x64/lib/python3.10/site-packages/httpx/_client.py\", line 929, in _send_handling_auth\n    response = self._send_handling_redirects(\n  File \"/opt/hostedtoolcache/Python/3.10.13/x64/lib/python3.10/site-packages/httpx/_client.py\", line 966, in _send_handling_redirects\n    response = self._send_single_request(request)\n  File \"/opt/hostedtoolcache/Python/3.10.13/x64/lib/python3.10/site-packages/httpx/_client.py\", line 1002, in _send_single_request\n    response = transport.handle_request(request)\n  File \"/opt/hostedtoolcache/Python/3.10.13/x64/lib/python3.10/site-packages/httpx/_transports/default.py\", line 227, in handle_request\n    with map_httpcore_exceptions():\n  File \"/opt/hostedtoolcache/Python/3.10.13/x64/lib/python3.10/contextlib.py\", line 153, in __exit__\n    self.gen.throw(typ, value, traceback)\n  File \"/opt/hostedtoolcache/Python/3.10.13/x64/lib/python3.10/site-packages/httpx/_transports/default.py\", line 83, in map_httpcore_exceptions\n    raise mapped_exc(message) from exc\nhttpx.ReadTimeout: The read operation timed out\n", "record": {"elapsed": {"repr": "0:00:07.684557", "seconds": 7.684557}, "exception": {"type": "ReadTimeout", "value": "The read operation timed out", "traceback": true}, "extra": {}, "file": {"name": "claim.py", "path": "/home/runner/work/egames4/egames4/epic/src/claim.py"}, "function": "run", "level": {"icon": "❌", "name": "ERROR", "no": 40}, "line": 138, "message": "An error has been caught in function 'run', process 'MainProcess' (4053), thread 'MainThread' (140424010996800):", "module": "claim", "name": "__main__", "process": {"id": 4053, "name": "MainProcess"}, "thread": {"id": 140424010996800, "name": "MainThread"}, "time": {"repr": "2023-10-14 12:43:00.365092+08:00", "timestamp": 1697258580.365092}}}
