{"text": "2023-11-09 12:44:18 | INFO    | __main__:stash:140 | run - {'image': '20231105', 'version': '0.9.3', 'role': 'EpicPlayer', 'headless': True, 'self_supervised': True}\n", "record": {"elapsed": {"repr": "0:00:05.263888", "seconds": 5.263888}, "exception": null, "extra": {"image": "20231105", "version": "0.9.3", "role": "EpicPlayer", "headless": true, "self_supervised": true}, "file": {"name": "claim.py", "path": "/home/runner/work/egames4/egames4/epic/src/claim.py"}, "function": "stash", "level": {"icon": "ℹ️", "name": "INFO", "no": 20}, "line": 140, "message": "run", "module": "claim", "name": "__main__", "process": {"id": 5324, "name": "MainProcess"}, "thread": {"id": 139844267985792, "name": "MainThread"}, "time": {"repr": "2023-11-09 12:44:18.582022+08:00", "timestamp": 1699505058.582022}}}
{"text": "2023-11-09 12:44:51 | ERROR    | __main__:run:167 | An error has been caught in function 'run', process 'MainProcess' (5324), thread 'MainThread' (139844267985792): - {}\nTraceback (most recent call last):\n  File \"/home/runner/work/egames4/egames4/epic/src/claim.py\", line 171, in <module>\n    asyncio.run(run())\n  File \"/opt/hostedtoolcache/Python/3.10.13/x64/lib/python3.10/asyncio/runners.py\", line 44, in run\n    return loop.run_until_complete(main)\n  File \"/opt/hostedtoolcache/Python/3.10.13/x64/lib/python3.10/asyncio/base_events.py\", line 636, in run_until_complete\n    self.run_forever()\n  File \"/opt/hostedtoolcache/Python/3.10.13/x64/lib/python3.10/asyncio/base_events.py\", line 603, in run_forever\n    self._run_once()\n  File \"/opt/hostedtoolcache/Python/3.10.13/x64/lib/python3.10/asyncio/base_events.py\", line 1909, in _run_once\n    handle._run()\n  File \"/opt/hostedtoolcache/Python/3.10.13/x64/lib/python3.10/asyncio/events.py\", line 80, in _run\n    self._context.run(self._callback, *self._args)\n> File \"/home/runner/work/egames4/egames4/epic/src/claim.py\", line 167, in run\n    await agent.stash()\n  File \"/home/runner/work/egames4/egames4/epic/src/claim.py\", line 158, in stash\n    if not await self.prelude_with_context(context):\n  File \"/home/runner/work/egames4/egames4/epic/src/claim.py\", line 72, in prelude_with_context\n    await page.goto(url, wait_until=\"networkidle\")\n  File \"/opt/hostedtoolcache/Python/3.10.13/x64/lib/python3.10/site-packages/playwright/async_api/_generated.py\", line 9251, in goto\n    await self._impl_obj.goto(\n  File \"/opt/hostedtoolcache/Python/3.10.13/x64/lib/python3.10/site-packages/playwright/_impl/_page.py\", line 473, in goto\n    return await self._main_frame.goto(**locals_to_params(locals()))\n  File \"/opt/hostedtoolcache/Python/3.10.13/x64/lib/python3.10/site-packages/playwright/_impl/_frame.py\", line 138, in goto\n    await self._channel.send(\"goto\", locals_to_params(locals()))\n  File \"/opt/hostedtoolcache/Python/3.10.13/x64/lib/python3.10/site-packages/playwright/_impl/_connection.py\", line 61, in send\n    return await self._connection.wrap_api_call(\n  File \"/opt/hostedtoolcache/Python/3.10.13/x64/lib/python3.10/site-packages/playwright/_impl/_connection.py\", line 490, in wrap_api_call\n    return await cb()\n  File \"/opt/hostedtoolcache/Python/3.10.13/x64/lib/python3.10/site-packages/playwright/_impl/_connection.py\", line 99, in inner_send\n    result = next(iter(done)).result()\nplaywright._impl._api_types.TimeoutError: Timeout 30000ms exceeded.\n=========================== logs ===========================\nnavigating to \"https://www.epicgames.com/account/creator-programs\", waiting until \"networkidle\"\n============================================================\n", "record": {"elapsed": {"repr": "0:00:38.143758", "seconds": 38.143758}, "exception": {"type": "TimeoutError", "value": "Timeout 30000ms exceeded.\n=========================== logs ===========================\nnavigating to \"https://www.epicgames.com/account/creator-programs\", waiting until \"networkidle\"\n============================================================", "traceback": true}, "extra": {}, "file": {"name": "claim.py", "path": "/home/runner/work/egames4/egames4/epic/src/claim.py"}, "function": "run", "level": {"icon": "❌", "name": "ERROR", "no": 40}, "line": 167, "message": "An error has been caught in function 'run', process 'MainProcess' (5324), thread 'MainThread' (139844267985792):", "module": "claim", "name": "__main__", "process": {"id": 5324, "name": "MainProcess"}, "thread": {"id": 139844267985792, "name": "MainThread"}, "time": {"repr": "2023-11-09 12:44:51.461892+08:00", "timestamp": 1699505091.461892}}}
